2022-07-29 18:11:07,583 numexpr.utils  INFO NumExpr defaulting to 8 threads.
2022-07-29 18:11:08,089 root  ERROR [Errno 2] No such file or directory: 'C:\\Users\\Rambabu\\Desktop\\Data Science Full Stack Developer\\Pandas\\Attribute DataSet'
Traceback (most recent call last):
  File "C:\Users\Rambabu\PycharmProjects\FirstpythonProject\Tasks\Task8\Question2.py", line 9, in <module>
    data = pd.read_csv(r'C:\Users\Rambabu\Desktop\Data Science Full Stack Developer\Pandas\Attribute DataSet')
  File "C:\Users\Rambabu\anaconda3\envs\FirstpythonProject\lib\site-packages\pandas\util\_decorators.py", line 311, in wrapper
    return func(*args, **kwargs)
  File "C:\Users\Rambabu\anaconda3\envs\FirstpythonProject\lib\site-packages\pandas\io\parsers\readers.py", line 680, in read_csv
    return _read(filepath_or_buffer, kwds)
  File "C:\Users\Rambabu\anaconda3\envs\FirstpythonProject\lib\site-packages\pandas\io\parsers\readers.py", line 575, in _read
    parser = TextFileReader(filepath_or_buffer, **kwds)
  File "C:\Users\Rambabu\anaconda3\envs\FirstpythonProject\lib\site-packages\pandas\io\parsers\readers.py", line 934, in __init__
    self._engine = self._make_engine(f, self.engine)
  File "C:\Users\Rambabu\anaconda3\envs\FirstpythonProject\lib\site-packages\pandas\io\parsers\readers.py", line 1218, in _make_engine
    self.handles = get_handle(  # type: ignore[call-overload]
  File "C:\Users\Rambabu\anaconda3\envs\FirstpythonProject\lib\site-packages\pandas\io\common.py", line 786, in get_handle
    handle = open(
FileNotFoundError: [Errno 2] No such file or directory: 'C:\\Users\\Rambabu\\Desktop\\Data Science Full Stack Developer\\Pandas\\Attribute DataSet'
2022-07-29 18:12:17,518 numexpr.utils  INFO NumExpr defaulting to 8 threads.
2022-07-29 18:12:17,833 root  ERROR [Errno 2] No such file or directory: 'C:\\Users\\Rambabu\\Desktop\\Data Science Full Stack Developer\\Pandas\\Attribute DataSet'
Traceback (most recent call last):
  File "C:\Users\Rambabu\PycharmProjects\FirstpythonProject\Tasks\Task8\Question2.py", line 9, in <module>
    data = pd.read_excel(r'C:\Users\Rambabu\Desktop\Data Science Full Stack Developer\Pandas\Attribute DataSet')
  File "C:\Users\Rambabu\anaconda3\envs\FirstpythonProject\lib\site-packages\pandas\util\_decorators.py", line 311, in wrapper
    return func(*args, **kwargs)
  File "C:\Users\Rambabu\anaconda3\envs\FirstpythonProject\lib\site-packages\pandas\io\excel\_base.py", line 457, in read_excel
    io = ExcelFile(io, storage_options=storage_options, engine=engine)
  File "C:\Users\Rambabu\anaconda3\envs\FirstpythonProject\lib\site-packages\pandas\io\excel\_base.py", line 1376, in __init__
    ext = inspect_excel_format(
  File "C:\Users\Rambabu\anaconda3\envs\FirstpythonProject\lib\site-packages\pandas\io\excel\_base.py", line 1250, in inspect_excel_format
    with get_handle(
  File "C:\Users\Rambabu\anaconda3\envs\FirstpythonProject\lib\site-packages\pandas\io\common.py", line 795, in get_handle
    handle = open(handle, ioargs.mode)
FileNotFoundError: [Errno 2] No such file or directory: 'C:\\Users\\Rambabu\\Desktop\\Data Science Full Stack Developer\\Pandas\\Attribute DataSet'
2022-07-29 18:22:24,414 numexpr.utils  INFO NumExpr defaulting to 8 threads.
2022-07-29 18:22:24,869 root  ERROR Missing optional dependency 'openpyxl'.  Use pip or conda to install openpyxl.
Traceback (most recent call last):
  File "C:\Users\Rambabu\anaconda3\envs\FirstpythonProject\lib\site-packages\pandas\compat\_optional.py", line 138, in import_optional_dependency
    module = importlib.import_module(name)
  File "C:\Users\Rambabu\anaconda3\envs\FirstpythonProject\lib\importlib\__init__.py", line 126, in import_module
    return _bootstrap._gcd_import(name[level:], package, level)
  File "<frozen importlib._bootstrap>", line 1050, in _gcd_import
  File "<frozen importlib._bootstrap>", line 1027, in _find_and_load
  File "<frozen importlib._bootstrap>", line 1004, in _find_and_load_unlocked
ModuleNotFoundError: No module named 'openpyxl'

During handling of the above exception, another exception occurred:

Traceback (most recent call last):
  File "C:\Users\Rambabu\PycharmProjects\FirstpythonProject\Tasks\Task8\Question2.py", line 9, in <module>
    data = pd.read_excel(r'C:\Users\Rambabu\Desktop\Data Science Full Stack Developer\Pandas\Attribute DataSet.xlsx')
  File "C:\Users\Rambabu\anaconda3\envs\FirstpythonProject\lib\site-packages\pandas\util\_decorators.py", line 311, in wrapper
    return func(*args, **kwargs)
  File "C:\Users\Rambabu\anaconda3\envs\FirstpythonProject\lib\site-packages\pandas\io\excel\_base.py", line 457, in read_excel
    io = ExcelFile(io, storage_options=storage_options, engine=engine)
  File "C:\Users\Rambabu\anaconda3\envs\FirstpythonProject\lib\site-packages\pandas\io\excel\_base.py", line 1419, in __init__
    self._reader = self._engines[engine](self._io, storage_options=storage_options)
  File "C:\Users\Rambabu\anaconda3\envs\FirstpythonProject\lib\site-packages\pandas\io\excel\_openpyxl.py", line 524, in __init__
    import_optional_dependency("openpyxl")
  File "C:\Users\Rambabu\anaconda3\envs\FirstpythonProject\lib\site-packages\pandas\compat\_optional.py", line 141, in import_optional_dependency
    raise ImportError(msg)
ImportError: Missing optional dependency 'openpyxl'.  Use pip or conda to install openpyxl.
2022-07-29 21:54:41,653 numexpr.utils  INFO NumExpr defaulting to 8 threads.
2022-07-29 21:56:09,131 numexpr.utils  INFO NumExpr defaulting to 8 threads.
2022-07-29 22:02:58,450 numexpr.utils  INFO NumExpr defaulting to 8 threads.
2022-07-29 22:04:22,755 numexpr.utils  INFO NumExpr defaulting to 8 threads.
2022-07-29 22:04:59,812 numexpr.utils  INFO NumExpr defaulting to 8 threads.
2022-07-29 22:05:00,197 root  ERROR 1366 (HY000): Incorrect integer value: '' for column 'Day17' at row 1
Traceback (most recent call last):
  File "C:\Users\Rambabu\anaconda3\envs\FirstpythonProject\lib\site-packages\mysql\connector\connection_cext.py", line 555, in cmd_query
    self._cmysql.query(
_mysql_connector.MySQLInterfaceError: Incorrect integer value: '' for column 'Day17' at row 1

The above exception was the direct cause of the following exception:

Traceback (most recent call last):
  File "C:\Users\Rambabu\PycharmProjects\FirstpythonProject\Tasks\Task8\Question2.py", line 79, in <module>
    cursor.execute(query, values)
  File "C:\Users\Rambabu\anaconda3\envs\FirstpythonProject\lib\site-packages\mysql\connector\cursor_cext.py", line 276, in execute
    result = self._cnx.cmd_query(
  File "C:\Users\Rambabu\anaconda3\envs\FirstpythonProject\lib\site-packages\mysql\connector\connection_cext.py", line 563, in cmd_query
    raise get_mysql_exception(
mysql.connector.errors.DatabaseError: 1366 (HY000): Incorrect integer value: '' for column 'Day17' at row 1
2022-07-29 22:05:12,486 numexpr.utils  INFO NumExpr defaulting to 8 threads.
2022-07-29 22:05:12,854 root  ERROR 1366 (HY000): Incorrect integer value: '' for column 'Day17' at row 1
Traceback (most recent call last):
  File "C:\Users\Rambabu\anaconda3\envs\FirstpythonProject\lib\site-packages\mysql\connector\connection_cext.py", line 555, in cmd_query
    self._cmysql.query(
_mysql_connector.MySQLInterfaceError: Incorrect integer value: '' for column 'Day17' at row 1

The above exception was the direct cause of the following exception:

Traceback (most recent call last):
  File "C:\Users\Rambabu\PycharmProjects\FirstpythonProject\Tasks\Task8\Question2.py", line 79, in <module>
    cursor.execute(query, values)
  File "C:\Users\Rambabu\anaconda3\envs\FirstpythonProject\lib\site-packages\mysql\connector\cursor_cext.py", line 276, in execute
    result = self._cnx.cmd_query(
  File "C:\Users\Rambabu\anaconda3\envs\FirstpythonProject\lib\site-packages\mysql\connector\connection_cext.py", line 563, in cmd_query
    raise get_mysql_exception(
mysql.connector.errors.DatabaseError: 1366 (HY000): Incorrect integer value: '' for column 'Day17' at row 1
2022-07-29 22:05:32,077 numexpr.utils  INFO NumExpr defaulting to 8 threads.
2022-07-29 22:05:32,437 root  ERROR 1366 (HY000): Incorrect integer value: '' for column 'Day17' at row 1
Traceback (most recent call last):
  File "C:\Users\Rambabu\anaconda3\envs\FirstpythonProject\lib\site-packages\mysql\connector\connection_cext.py", line 555, in cmd_query
    self._cmysql.query(
_mysql_connector.MySQLInterfaceError: Incorrect integer value: '' for column 'Day17' at row 1

The above exception was the direct cause of the following exception:

Traceback (most recent call last):
  File "C:\Users\Rambabu\PycharmProjects\FirstpythonProject\Tasks\Task8\Question2.py", line 79, in <module>
    cursor.execute(query, values)
  File "C:\Users\Rambabu\anaconda3\envs\FirstpythonProject\lib\site-packages\mysql\connector\cursor_cext.py", line 276, in execute
    result = self._cnx.cmd_query(
  File "C:\Users\Rambabu\anaconda3\envs\FirstpythonProject\lib\site-packages\mysql\connector\connection_cext.py", line 563, in cmd_query
    raise get_mysql_exception(
mysql.connector.errors.DatabaseError: 1366 (HY000): Incorrect integer value: '' for column 'Day17' at row 1
2022-07-29 22:06:55,248 numexpr.utils  INFO NumExpr defaulting to 8 threads.
2022-07-29 22:09:54,767 numexpr.utils  INFO NumExpr defaulting to 8 threads.
2022-07-29 22:09:55,226 root  ERROR 1366 (HY000): Incorrect integer value: '' for column 'Day17' at row 1
Traceback (most recent call last):
  File "C:\Users\Rambabu\anaconda3\envs\FirstpythonProject\lib\site-packages\mysql\connector\connection_cext.py", line 555, in cmd_query
    self._cmysql.query(
_mysql_connector.MySQLInterfaceError: Incorrect integer value: '' for column 'Day17' at row 1

The above exception was the direct cause of the following exception:

Traceback (most recent call last):
  File "C:\Users\Rambabu\PycharmProjects\FirstpythonProject\Tasks\Task8\Question2.py", line 79, in <module>
    cursor.execute(query, values)
  File "C:\Users\Rambabu\anaconda3\envs\FirstpythonProject\lib\site-packages\mysql\connector\cursor_cext.py", line 276, in execute
    result = self._cnx.cmd_query(
  File "C:\Users\Rambabu\anaconda3\envs\FirstpythonProject\lib\site-packages\mysql\connector\connection_cext.py", line 563, in cmd_query
    raise get_mysql_exception(
mysql.connector.errors.DatabaseError: 1366 (HY000): Incorrect integer value: '' for column 'Day17' at row 1
2022-07-29 22:12:28,556 numexpr.utils  INFO NumExpr defaulting to 8 threads.
2022-07-29 22:12:29,052 root  ERROR 1366 (HY000): Incorrect integer value: '' for column 'Day17' at row 1
Traceback (most recent call last):
  File "C:\Users\Rambabu\anaconda3\envs\FirstpythonProject\lib\site-packages\mysql\connector\connection_cext.py", line 555, in cmd_query
    self._cmysql.query(
_mysql_connector.MySQLInterfaceError: Incorrect integer value: '' for column 'Day17' at row 1

The above exception was the direct cause of the following exception:

Traceback (most recent call last):
  File "C:\Users\Rambabu\PycharmProjects\FirstpythonProject\Tasks\Task8\Question2.py", line 79, in <module>
    cursor.execute(query, values)
  File "C:\Users\Rambabu\anaconda3\envs\FirstpythonProject\lib\site-packages\mysql\connector\cursor_cext.py", line 276, in execute
    result = self._cnx.cmd_query(
  File "C:\Users\Rambabu\anaconda3\envs\FirstpythonProject\lib\site-packages\mysql\connector\connection_cext.py", line 563, in cmd_query
    raise get_mysql_exception(
mysql.connector.errors.DatabaseError: 1366 (HY000): Incorrect integer value: '' for column 'Day17' at row 1
2022-07-29 22:13:32,519 numexpr.utils  INFO NumExpr defaulting to 8 threads.
2022-07-29 22:13:32,891 root  ERROR 1366 (HY000): Incorrect integer value: '' for column 'Day17' at row 1
Traceback (most recent call last):
  File "C:\Users\Rambabu\anaconda3\envs\FirstpythonProject\lib\site-packages\mysql\connector\connection_cext.py", line 555, in cmd_query
    self._cmysql.query(
_mysql_connector.MySQLInterfaceError: Incorrect integer value: '' for column 'Day17' at row 1

The above exception was the direct cause of the following exception:

Traceback (most recent call last):
  File "C:\Users\Rambabu\PycharmProjects\FirstpythonProject\Tasks\Task8\Question2.py", line 79, in <module>
    cursor.execute(query, values)
  File "C:\Users\Rambabu\anaconda3\envs\FirstpythonProject\lib\site-packages\mysql\connector\cursor_cext.py", line 276, in execute
    result = self._cnx.cmd_query(
  File "C:\Users\Rambabu\anaconda3\envs\FirstpythonProject\lib\site-packages\mysql\connector\connection_cext.py", line 563, in cmd_query
    raise get_mysql_exception(
mysql.connector.errors.DatabaseError: 1366 (HY000): Incorrect integer value: '' for column 'Day17' at row 1
2022-07-29 22:14:00,595 numexpr.utils  INFO NumExpr defaulting to 8 threads.
2022-07-29 22:14:01,061 root  ERROR 1366 (HY000): Incorrect integer value: '' for column 'Day17' at row 1
Traceback (most recent call last):
  File "C:\Users\Rambabu\anaconda3\envs\FirstpythonProject\lib\site-packages\mysql\connector\connection_cext.py", line 555, in cmd_query
    self._cmysql.query(
_mysql_connector.MySQLInterfaceError: Incorrect integer value: '' for column 'Day17' at row 1

The above exception was the direct cause of the following exception:

Traceback (most recent call last):
  File "C:\Users\Rambabu\PycharmProjects\FirstpythonProject\Tasks\Task8\Question2.py", line 79, in <module>
    cursor.execute(query, values)
  File "C:\Users\Rambabu\anaconda3\envs\FirstpythonProject\lib\site-packages\mysql\connector\cursor_cext.py", line 276, in execute
    result = self._cnx.cmd_query(
  File "C:\Users\Rambabu\anaconda3\envs\FirstpythonProject\lib\site-packages\mysql\connector\connection_cext.py", line 563, in cmd_query
    raise get_mysql_exception(
mysql.connector.errors.DatabaseError: 1366 (HY000): Incorrect integer value: '' for column 'Day17' at row 1
2022-07-29 22:20:42,968 numexpr.utils  INFO NumExpr defaulting to 8 threads.
2022-07-29 22:20:43,948 root  ERROR 1366 (HY000): Incorrect integer value: 'Orders' for column 'Day13' at row 1
Traceback (most recent call last):
  File "C:\Users\Rambabu\anaconda3\envs\FirstpythonProject\lib\site-packages\mysql\connector\connection_cext.py", line 555, in cmd_query
    self._cmysql.query(
_mysql_connector.MySQLInterfaceError: Incorrect integer value: 'Orders' for column 'Day13' at row 1

The above exception was the direct cause of the following exception:

Traceback (most recent call last):
  File "C:\Users\Rambabu\PycharmProjects\FirstpythonProject\Tasks\Task8\Question2.py", line 79, in <module>
    cursor.execute(query, values)
  File "C:\Users\Rambabu\anaconda3\envs\FirstpythonProject\lib\site-packages\mysql\connector\cursor_cext.py", line 276, in execute
    result = self._cnx.cmd_query(
  File "C:\Users\Rambabu\anaconda3\envs\FirstpythonProject\lib\site-packages\mysql\connector\connection_cext.py", line 563, in cmd_query
    raise get_mysql_exception(
mysql.connector.errors.DatabaseError: 1366 (HY000): Incorrect integer value: 'Orders' for column 'Day13' at row 1
2022-07-29 22:23:36,289 numexpr.utils  INFO NumExpr defaulting to 8 threads.
2022-07-29 22:23:37,784 root  ERROR 1366 (HY000): Incorrect integer value: 'Removed' for column 'Day8' at row 1
Traceback (most recent call last):
  File "C:\Users\Rambabu\anaconda3\envs\FirstpythonProject\lib\site-packages\mysql\connector\connection_cext.py", line 555, in cmd_query
    self._cmysql.query(
_mysql_connector.MySQLInterfaceError: Incorrect integer value: 'Removed' for column 'Day8' at row 1

The above exception was the direct cause of the following exception:

Traceback (most recent call last):
  File "C:\Users\Rambabu\PycharmProjects\FirstpythonProject\Tasks\Task8\Question2.py", line 79, in <module>
    cursor.execute(query, values)
  File "C:\Users\Rambabu\anaconda3\envs\FirstpythonProject\lib\site-packages\mysql\connector\cursor_cext.py", line 276, in execute
    result = self._cnx.cmd_query(
  File "C:\Users\Rambabu\anaconda3\envs\FirstpythonProject\lib\site-packages\mysql\connector\connection_cext.py", line 563, in cmd_query
    raise get_mysql_exception(
mysql.connector.errors.DatabaseError: 1366 (HY000): Incorrect integer value: 'Removed' for column 'Day8' at row 1
2022-07-29 22:25:10,433 numexpr.utils  INFO NumExpr defaulting to 8 threads.
